<mujoco model="quad_world">
    <compiler inertiafromgeom="true" angle="degree"/>

    <default>
        <joint limited="true" damping="1" armature="0"/>
        <geom condim="1" material="matgeom"/>
        <motor ctrlrange="-.4 .4" ctrllimited="true"/>
    </default>

    <option timestep="0.005" iterations="50" tolerance="1e-10" solver="Newton" jacobian="dense" cone="pyramidal"/>

    <size nconmax="50" njmax="200" nstack="10000"/>

    <visual>
        <map force="0.1" zfar="30"/>
        <rgba haze="0.15 0.25 0.35 1"/>
        <quality shadowsize="2048"/>
        <global offwidth="800" offheight="800"/>
    </visual>

    <asset>
        <texture type="skybox" builtin="gradient" rgb1="0.3 0.5 0.7" rgb2="0 0 0" width="512" height="512"/> 

        <texture name="texplane" type="2d" builtin="checker" rgb1=".2 .3 .4" rgb2=".1 0.15 0.2" width="512" height="512" mark="cross" markrgb=".8 .8 .8"/>  

        <texture name="texgeom" type="cube" builtin="flat" mark="cross" width="127" height="1278" 
            rgb1="0.8 0.6 0.4" rgb2="0.8 0.6 0.4" markrgb="1 1 1" random="0.01"/>  

        <material name="matplane" reflectance="0.3" texture="texplane" texrepeat="1 1" texuniform="true"/>

        <material name="matgeom" texture="texgeom" texuniform="true" rgba="0.8 0.6 .4 1"/>
    </asset>

    <worldbody>
        <geom name="floor" pos="0 0 0" size="0 0 .25" type="plane" material="matplane" condim="3"/>

        <light directional="false" diffuse=".2 .2 .2" specular="0 0 0" pos="0 0 5" dir="0 0 -1" castshadow="false"/>
        <light mode="targetbodycom" target="torso" directional="false" diffuse=".8 .8 .8" specular="0.3 0.3 0.3" pos="0 0 4.0" dir="0 0 -1"/>       
	<body name="torso" pos="0 0 2">
        <freejoint name="root"/>
        <geom name="torso_geom" pos="0 0 0" size="0.4 0.2 0.1" type="box"/>
        <body name="front_left_leg" pos="0.35 0.1 -0.075">
          <geom fromto="0.0 0.0 0.0 0.0 0.0 -0.4" name="aux_1_geom" size="0.06" type="capsule" rgba    =".8 .5 .3 1"/>
	  <joint axis = "0 1 0" name = "hip_1" pos= "0.0 0.0 0.0" range="-40 40" type="hinge"/>
	  <joint axis = "1 0 0" name = "hip_side_1" pos="0.0 0.0 0.0" range="-10 10" type ="hinge"/>
        </body>
        <body name="front_right_leg" pos="0.35 -0.1 -0.075">
                <geom fromto="0.0 0.0 0.0 0.0 0.0 -0.4" name="aux_2_geom" size="0.06" type="capsule"/>           
		<joint axis="0 1 0" name="hip_2" pos="0.0 0.0 0.0" range="-40 40" type="hinge"/>
		<joint axis = "1 0 0" name = "hip_side_2" pos="0.0 0.0 0.0" range="-10 10" type ="hinge"/>

        </body>
        <body name="left_back_leg" pos="-0.35 0.1 -0.075">
          <geom fromto="0.0 0.0 0.0 0.0 0.0 -0.4" name="aux_3_geom" size="0.06" type="capsule"/>
	  <joint axis="0 1 0" name="hip_3" pos="0.0 0.0 0.0" range="-40 40" type="hinge"/>
	  <joint axis = "1 0 0" name = "hip_side_3" pos="0.0 0.0 0.0" range="-10 10" type ="hinge"/>
        </body>
        <body name="right_back_leg" pos="-0.35 -0.1 -0.075">
          <geom fromto="0.0 0.0 0.0 0.0 0.0 -0.4" name="aux_4_geom" size="0.06" type="capsule" rgba    =".8 .5 .3 1"/>
	  <joint axis="0 1 0" name="hip_4" pos="0.0 0.0 0.0" range="-40 40" type="hinge"/>
	  <joint axis = "1 0 0" name = "hip_side_4" pos="0.0 0.0 0.0" range="-10 10" type ="hinge"/>
         </body>
      </body>
      
    </worldbody>

    <actuator>
     <motor ctrllimited="true" ctrlrange="-5.0 5.0" joint="hip_4" gear="150"/>
     <motor ctrllimited="true" ctrlrange="-5.0 5.0" joint="hip_1" gear="150"/>
     <motor ctrllimited="true" ctrlrange="-5.0 5.0" joint="hip_2" gear="150"/>
     <motor ctrllimited="true" ctrlrange="-5.0 5.0" joint="hip_3" gear="150"/>
     <motor ctrllimited="true" ctrlrange="-5.0 5.0" joint="hip_side_1" gear="150"/>
     <motor ctrllimited="true" ctrlrange="-5.0 5.0" joint="hip_side_2" gear="150"/>
     <motor ctrllimited="true" ctrlrange="-5.0 5.0" joint="hip_side_3" gear="150"/>
     <motor ctrllimited="true" ctrlrange="-5.0 5.0" joint="hip_side_4" gear="150"/>
    </actuator>

</mujoco>
