#VRML_SIM R2019a utf8
WorldInfo {
}
Viewpoint {
  orientation 0.03511010992998444 -0.9818642385075261 -0.18630592400871274 3.540320083494632
  position 8.161354783857009 7.46325090156485 -16.947030516363444
}
TexturedBackground {
}
TexturedBackgroundLight {
}
Floor {
  size 20 20
}
DEF terrainFloor Solid {
  translation -3 1 -3
  children [
    DEF floorShape Shape {
      appearance PBRAppearance {
        baseColor 0.7 0.8 0.2
        roughness 1
      }
      geometry DEF boxGeom1 Box {
        size 2 0.1 5
      }
    }
  ]
  name "solid(1)"
  boundingObject USE boxGeom1
}
DEF supaMan Robot {
  controller "withSupervisorObstacleCourse"
  supervisor TRUE
}
DEF randTerrainHolder Transform {
  translation -3 0 -3
}
DEF obstCube Solid {
  translation 0 0.07000000000000002 2.9299999999999957
  children [
    Shape {
      appearance PBRAppearance {
        baseColor 0.2 1 0.5
      }
      geometry DEF bGeom1 Box {
        size 0.1 0.1 0.1
      }
    }
  ]
  boundingObject USE bGeom1
  physics Physics {
    mass 0.8
  }
}
DEF secondVersionWithMotors Robot {
  translation 3.09 0.28 -2
  children [
    DEF perfectTorso Solid {
      translation -0.2575 0 -0.1
      children [
        DEF shoulderHip Hinge2Joint {
          jointParameters HingeJointParameters {
            anchor 0.395 0.025 0.2
            minStop -0.5
            maxStop 0.5
          }
          jointParameters2 JointParameters {
            minStop -3.14
            maxStop 3.14
          }
          device [
            DEF RotMot1 RotationalMotor {
              name "rotational motor1"
              acceleration 1.5
              maxVelocity 3
              minPosition -0.5
              maxPosition 0.5
            }
          ]
          device2 [
            DEF RotMot2 RotationalMotor {
              name "rotational motor2"
              acceleration 1.5
              maxVelocity 3
              minPosition -3.14
              maxPosition 3.14
            }
          ]
          endPoint Solid {
            translation 0.395 0.025 0.21250000000000002
            rotation 0 1 0 3.141592644
            children [
              DEF upperlegbodyconnector Shape {
                appearance PBRAppearance {
                  baseColor 0.04 1 0.68
                }
                geometry Box {
                  size 0.05 0.05 0.025
                }
              }
              Solid {
                translation 0 -0.065 -0.0275
                children [
                  DEF upperLeg Shape {
                    appearance PBRAppearance {
                    }
                    geometry Box {
                      size 0.05 0.18 0.03
                    }
                  }
                  Transform {
                    translation 0 -0.11 0.026
                    children [
                      SliderJoint {
                        jointParameters JointParameters {
                          position 0.01
                          axis 0 1 0
                          minStop -0.01
                          maxStop 0.085
                        }
                        device [
                          DEF LinMot1 LinearMotor {
                            name "linear motor1"
                            acceleration 0.75
                            maxVelocity 0.2
                            minPosition -0.01
                            maxPosition 0.085
                            maxForce 58.5
                          }
                        ]
                        endPoint Solid {
                          translation 0 0.01 0
                          children [
                            SliderJoint {
                              jointParameters JointParameters {
                                axis 0 1 0
                                maxStop 0.04
                                springConstant 3000
                              }
                              endPoint Solid {
                                translation 0 -0.09 0
                                children [
                                  DEF foot Shape {
                                    appearance PBRAppearance {
                                      baseColor 1 0.2 0.1
                                    }
                                    geometry Capsule {
                                      height 0.03
                                      radius 0.01
                                    }
                                  }
                                ]
                                boundingObject USE foot
                                physics Physics {
                                  density -1
                                  mass 0.1
                                }
                              }
                            }
                            DEF lowerandupperlegconnector Shape {
                              appearance PBRAppearance {
                                baseColor 0.5 0.9 0.1
                              }
                              geometry Box {
                                size 0.025 0.06 0.02
                              }
                            }
                          ]
                          boundingObject USE lowerandupperlegconnector
                          physics Physics {
                            mass 0.15
                          }
                        }
                      }
                    ]
                  }
                ]
                boundingObject USE upperLeg
                physics Physics {
                  mass 0.17
                }
              }
            ]
            name "solid(3)"
            boundingObject USE upperlegbodyconnector
            physics Physics {
              mass 0.03
            }
          }
        }
        DEF shoulderHip2 Hinge2Joint {
          jointParameters HingeJointParameters {
            anchor 0.12 0.025 0.2
            minStop -0.5
            maxStop 0.5
          }
          jointParameters2 JointParameters {
            minStop -3.14
            maxStop 3.14
          }
          device [
            RotationalMotor {
              name "rotational motor3"
              acceleration 1.5
              maxVelocity 3
              minPosition -0.5
              maxPosition 0.5
            }
          ]
          device2 [
            RotationalMotor {
              name "rotational motor4"
              acceleration 1.5
              maxVelocity 3
              minPosition -3.14
              maxPosition 3.14
            }
          ]
          endPoint Solid {
            translation 0.12000000057538757 0.025 0.21250000000000002
            rotation 0 1 0 3.141592644
            children [
              DEF upperlegbodyconnector Shape {
                appearance PBRAppearance {
                  baseColor 0.04 1 0.68
                }
                geometry DEF boxer1 Box {
                  size 0.05 0.05 0.025
                }
              }
              Solid {
                translation 0 -0.065 -0.0275
                children [
                  DEF upperLeg Shape {
                    appearance PBRAppearance {
                    }
                    geometry Box {
                      size 0.05 0.18 0.03
                    }
                  }
                  Transform {
                    translation 0 -0.11 0.026
                    children [
                      SliderJoint {
                        jointParameters JointParameters {
                          position 0.01
                          axis 0 1 0
                          minStop -0.01
                          maxStop 0.085
                        }
                        device [
                          LinearMotor {
                            name "linear motor4"
                            acceleration 0.75
                            maxVelocity 0.2
                            minPosition -0.01
                            maxPosition 0.085
                            maxForce 58.5
                          }
                        ]
                        endPoint Solid {
                          translation 0 0.01 0
                          children [
                            SliderJoint {
                              jointParameters JointParameters {
                                axis 0 1 0
                                maxStop 0.04
                                springConstant 3000
                              }
                              endPoint Solid {
                                translation 0 -0.09 0
                                children [
                                  DEF foot Shape {
                                    appearance PBRAppearance {
                                      baseColor 1 0.2 0.1
                                    }
                                    geometry Capsule {
                                      height 0.03
                                      radius 0.01
                                    }
                                  }
                                ]
                                boundingObject USE foot
                                physics Physics {
                                  density -1
                                  mass 0.1
                                }
                              }
                            }
                            DEF lowerandupperlegconnector Shape {
                              appearance PBRAppearance {
                                baseColor 0.5 0.9 0.1
                              }
                              geometry Box {
                                size 0.025 0.06 0.02
                              }
                            }
                          ]
                          boundingObject USE lowerandupperlegconnector
                          physics Physics {
                            density -1
                            mass 0.15
                          }
                        }
                      }
                    ]
                  }
                ]
                boundingObject USE upperLeg
                physics Physics {
                  density -1
                  mass 0.17
                }
              }
            ]
            name "solid(2)"
            boundingObject USE upperlegbodyconnector
            physics Physics {
              density -1
              mass 0.03
            }
          }
        }
        DEF shoulderHip3 Hinge2Joint {
          jointParameters HingeJointParameters {
            anchor 0.395 0.025 0
            minStop -0.5
            maxStop 0.5
          }
          jointParameters2 JointParameters {
            minStop -3.14
            maxStop 3.14
          }
          device [
            RotationalMotor {
              name "rotational motor5"
              acceleration 1.5
              maxVelocity 3
              minPosition -0.5
              maxPosition 0.5
            }
          ]
          device2 [
            RotationalMotor {
              name "rotational motor6"
              acceleration 1.5
              maxVelocity 3
              minPosition -3.14
              maxPosition 3.14
            }
          ]
          endPoint Solid {
            translation 0.395 0.025 -0.0125
            children [
              DEF upperlegbodyconnector Shape {
                appearance PBRAppearance {
                  baseColor 0.04 1 0.68
                }
                geometry Box {
                  size 0.05 0.05 0.025
                }
              }
              Solid {
                translation 0 -0.065 -0.0275
                children [
                  DEF upperLeg Shape {
                    appearance PBRAppearance {
                    }
                    geometry Box {
                      size 0.05 0.18 0.03
                    }
                  }
                  Transform {
                    translation 0 -0.11 0.026
                    children [
                      SliderJoint {
                        jointParameters JointParameters {
                          position 0.01
                          axis 0 1 0
                          minStop -0.01
                          maxStop 0.085
                        }
                        device [
                          LinearMotor {
                            name "linear motor2"
                            acceleration 0.75
                            maxVelocity 0.2
                            minPosition -0.01
                            maxPosition 0.085
                            maxForce 58.5
                          }
                        ]
                        endPoint Solid {
                          translation 0 0.01 0
                          children [
                            SliderJoint {
                              jointParameters JointParameters {
                                axis 0 1 0
                                maxStop 0.04
                                springConstant 3000
                              }
                              endPoint Solid {
                                translation 0 -0.09 0
                                children [
                                  DEF foot Shape {
                                    appearance PBRAppearance {
                                      baseColor 1 0.2 0.1
                                    }
                                    geometry Capsule {
                                      height 0.03
                                      radius 0.01
                                    }
                                  }
                                ]
                                boundingObject USE foot
                                physics Physics {
                                  density -1
                                  mass 0.1
                                }
                              }
                            }
                            DEF lowerandupperlegconnector Shape {
                              appearance PBRAppearance {
                                baseColor 0.5 0.9 0.1
                              }
                              geometry Box {
                                size 0.025 0.06 0.02
                              }
                            }
                          ]
                          boundingObject USE lowerandupperlegconnector
                          physics Physics {
                            density -1
                            mass 0.15
                          }
                        }
                      }
                    ]
                  }
                ]
                boundingObject USE upperLeg
                physics Physics {
                  density -1
                  mass 0.17
                }
              }
            ]
            name "solid(1)"
            boundingObject USE upperlegbodyconnector
            physics Physics {
              density -1
              mass 0.03
              centerOfMass [
                0 0 0
              ]
            }
          }
        }
        DEF BetterTorso Shape {
          appearance PBRAppearance {
            baseColor 1 0.2 0.65
          }
          geometry IndexedFaceSet {
            coord Coordinate {
              point [
                0 0 0
                0 0 0.2
                0 0.05 0
                0 0.05 0.2
                0 0.14 0.04
                0 0.14 0.16
                0.515 0 0
                0.515 0 0.2
                0.515 0.05 0
                0.515 0.05 0.2
                0.515 0.14 0.04
                0.515 0.14 0.16
              ]
            }
            coordIndex [
              0, 1, 2, -1, 2, 1, 3, -1, 2, 3, 4, -1, 4, 3, 5, -1, 1, 7, 3, -1, 3, 7, 9, -1, 3, 9, 5, -1, 5, 9, 11, -1, 4, 5, 11, -1, 4, 11, 10, -1, 4, 10, 8, -1, 2, 4, 8, -1, 0, 2, 6, -1, 2, 8, 6, -1, 0, 6, 1, -1, 1, 6, 7, -1, 6, 8, 7, -1, 7, 8, 9, -1, 8, 10, 9, -1, 10, 11, 9
            ]
          }
        }
        DEF shoulderHip4 Hinge2Joint {
          jointParameters HingeJointParameters {
            anchor 0.12 0.025 0
            minStop -0.5
            maxStop 0.5
          }
          jointParameters2 JointParameters {
            minStop -3.14
            maxStop 3.14
          }
          device [
            RotationalMotor {
              name "rotational motor7"
              acceleration 1.5
              maxVelocity 3
              minPosition -0.5
              maxPosition 0.5
            }
          ]
          device2 [
            RotationalMotor {
              name "rotational motor8"
              acceleration 1.5
              maxVelocity 3
              minPosition -3.14
              maxPosition 3.14
            }
          ]
          endPoint Solid {
            translation 0.12 0.025 -0.0125
            children [
              DEF upperlegbodyconnector Shape {
                appearance PBRAppearance {
                  baseColor 0.04 1 0.68
                }
                geometry Box {
                  size 0.05 0.05 0.025
                }
              }
              Solid {
                translation 0 -0.065 -0.0275
                children [
                  DEF upperLeg Shape {
                    appearance PBRAppearance {
                    }
                    geometry Box {
                      size 0.05 0.18 0.03
                    }
                  }
                  Transform {
                    translation 0 -0.11 0.026
                    children [
                      SliderJoint {
                        jointParameters JointParameters {
                          position 0.01
                          axis 0 1 0
                          minStop -0.01
                          maxStop 0.085
                        }
                        device [
                          LinearMotor {
                            name "linear motor3"
                            acceleration 0.75
                            maxVelocity 0.2
                            minPosition -0.01
                            maxPosition 0.085
                            maxForce 58.5
                          }
                        ]
                        endPoint Solid {
                          translation 0 0.01 0
                          children [
                            SliderJoint {
                              jointParameters JointParameters {
                                axis 0 1 0
                                maxStop 0.04
                                springConstant 3000
                              }
                              endPoint Solid {
                                translation 0 -0.09 0
                                children [
                                  DEF foot Shape {
                                    appearance PBRAppearance {
                                      baseColor 1 0.2 0.1
                                    }
                                    geometry Capsule {
                                      height 0.03
                                      radius 0.01
                                    }
                                  }
                                ]
                                boundingObject USE foot
                                physics Physics {
                                  density -1
                                  mass 0.1
                                }
                              }
                            }
                            DEF lowerandupperlegconnector Shape {
                              appearance PBRAppearance {
                                baseColor 0.5 0.9 0.1
                              }
                              geometry Box {
                                size 0.025 0.06 0.02
                              }
                            }
                          ]
                          boundingObject USE lowerandupperlegconnector
                          physics Physics {
                            density -1
                            mass 0.15
                          }
                        }
                      }
                    ]
                  }
                ]
                boundingObject USE upperLeg
                physics Physics {
                  density -1
                  mass 0.17
                }
              }
            ]
            boundingObject USE upperlegbodyconnector
            physics Physics {
              density -1
              mass 0.03
            }
          }
        }
      ]
      boundingObject USE BetterTorso
      physics Physics {
        density -1
        mass 12
      }
    }
  ]
  name "robot(2)"
  physics Physics {
    centerOfMass [
      0 0.0384446 0
    ]
  }
  controller ""
  battery [
    500000, 500000, 0
  ]
  cpuConsumption 0
  selfCollision TRUE
}
DEF secondVersion Robot {
  translation 8.089999999999984 1.680000000000001 7.699999999999973
  children [
    DEF perfectTorso Solid {
      translation -0.2575 0 -0.1
      children [
        DEF shoulderHip Hinge2Joint {
          jointParameters HingeJointParameters {
            anchor 0.395 0.025 0.2
            minStop -0.5
            maxStop 0.5
          }
          jointParameters2 JointParameters {
            minStop -3.14
            maxStop 3.14
          }
          endPoint Solid {
            translation 0.395 0.025 0.21250000000000002
            rotation 0 1 0 3.141592644
            children [
              DEF upperlegbodyconnector Shape {
                appearance PBRAppearance {
                  baseColor 0.04 1 0.68
                }
                geometry Box {
                  size 0.05 0.05 0.025
                }
              }
              Solid {
                translation 0 -0.065 -0.0275
                children [
                  DEF upperLeg Shape {
                    appearance PBRAppearance {
                    }
                    geometry Box {
                      size 0.05 0.18 0.03
                    }
                  }
                  Transform {
                    translation 0 -0.11 0.026
                    children [
                      SliderJoint {
                        jointParameters JointParameters {
                          axis 0 1 0
                          maxStop 0.085
                          springConstant 2
                        }
                        endPoint Solid {
                          children [
                            SliderJoint {
                              jointParameters JointParameters {
                                axis 0 1 0
                                maxStop 0.04
                                springConstant 3000
                              }
                              endPoint Solid {
                                translation 0 -0.09 0
                                children [
                                  DEF foot Shape {
                                    appearance PBRAppearance {
                                      baseColor 1 0.2 0.1
                                    }
                                    geometry Capsule {
                                      height 0.03
                                      radius 0.01
                                    }
                                  }
                                ]
                                boundingObject USE foot
                                physics Physics {
                                  density -1
                                  mass 0.1
                                }
                              }
                            }
                            DEF lowerandupperlegconnector Shape {
                              appearance PBRAppearance {
                                baseColor 0.5 0.9 0.1
                              }
                              geometry Box {
                                size 0.025 0.06 0.02
                              }
                            }
                          ]
                          boundingObject USE lowerandupperlegconnector
                          physics Physics {
                            mass 0.15
                          }
                        }
                      }
                    ]
                  }
                ]
                boundingObject USE upperLeg
                physics Physics {
                  mass 0.17
                }
              }
            ]
            name "solid(3)"
            boundingObject USE upperlegbodyconnector
            physics Physics {
              mass 0.03
            }
          }
        }
        DEF shoulderHip2 Hinge2Joint {
          jointParameters HingeJointParameters {
            anchor 0.12 0.025 0.2
            minStop -0.5
            maxStop 0.5
          }
          jointParameters2 JointParameters {
            minStop -3.14
            maxStop 3.14
          }
          endPoint Solid {
            translation 0.12000000057538757 0.025 0.21250000000000002
            rotation 0 1 0 3.141592644
            children [
              DEF upperlegbodyconnector Shape {
                appearance PBRAppearance {
                  baseColor 0.04 1 0.68
                }
                geometry DEF boxer2 Box {
                  size 0.05 0.05 0.025
                }
              }
              Solid {
                translation 0 -0.065 -0.0275
                children [
                  DEF upperLeg Shape {
                    appearance PBRAppearance {
                    }
                    geometry Box {
                      size 0.05 0.18 0.03
                    }
                  }
                  Transform {
                    translation 0 -0.11 0.026
                    children [
                      SliderJoint {
                        jointParameters JointParameters {
                          axis 0 1 0
                          maxStop 0.085
                        }
                        endPoint Solid {
                          children [
                            SliderJoint {
                              jointParameters JointParameters {
                                axis 0 1 0
                                maxStop 0.04
                                springConstant 3000
                              }
                              endPoint Solid {
                                translation 0 -0.09 0
                                children [
                                  DEF foot Shape {
                                    appearance PBRAppearance {
                                      baseColor 1 0.2 0.1
                                    }
                                    geometry Capsule {
                                      height 0.03
                                      radius 0.01
                                    }
                                  }
                                ]
                                boundingObject USE foot
                                physics Physics {
                                  density -1
                                  mass 0.1
                                }
                              }
                            }
                            DEF lowerandupperlegconnector Shape {
                              appearance PBRAppearance {
                                baseColor 0.5 0.9 0.1
                              }
                              geometry Box {
                                size 0.025 0.06 0.02
                              }
                            }
                          ]
                          boundingObject USE lowerandupperlegconnector
                          physics Physics {
                            density -1
                            mass 0.15
                          }
                        }
                      }
                    ]
                  }
                ]
                boundingObject USE upperLeg
                physics Physics {
                  density -1
                  mass 0.17
                }
              }
            ]
            name "solid(2)"
            boundingObject USE upperlegbodyconnector
            physics Physics {
              density -1
              mass 0.03
            }
          }
        }
        DEF shoulderHip3 Hinge2Joint {
          jointParameters HingeJointParameters {
            anchor 0.395 0.025 0
            minStop -0.5
            maxStop 0.5
          }
          jointParameters2 JointParameters {
            minStop -3.14
            maxStop 3.14
          }
          endPoint Solid {
            translation 0.395 0.025 -0.0125
            children [
              DEF upperlegbodyconnector Shape {
                appearance PBRAppearance {
                  baseColor 0.04 1 0.68
                }
                geometry Box {
                  size 0.05 0.05 0.025
                }
              }
              Solid {
                translation 0 -0.065 -0.0275
                children [
                  DEF upperLeg Shape {
                    appearance PBRAppearance {
                    }
                    geometry Box {
                      size 0.05 0.18 0.03
                    }
                  }
                  Transform {
                    translation 0 -0.11 0.026
                    children [
                      SliderJoint {
                        jointParameters JointParameters {
                          axis 0 1 0
                          maxStop 0.085
                        }
                        endPoint Solid {
                          children [
                            SliderJoint {
                              jointParameters JointParameters {
                                axis 0 1 0
                                maxStop 0.04
                                springConstant 3000
                              }
                              endPoint Solid {
                                translation 0 -0.09 0
                                children [
                                  DEF foot Shape {
                                    appearance PBRAppearance {
                                      baseColor 1 0.2 0.1
                                    }
                                    geometry Capsule {
                                      height 0.03
                                      radius 0.01
                                    }
                                  }
                                ]
                                boundingObject USE foot
                                physics Physics {
                                  density -1
                                  mass 0.1
                                }
                              }
                            }
                            DEF lowerandupperlegconnector Shape {
                              appearance PBRAppearance {
                                baseColor 0.5 0.9 0.1
                              }
                              geometry Box {
                                size 0.025 0.06 0.02
                              }
                            }
                          ]
                          boundingObject USE lowerandupperlegconnector
                          physics Physics {
                            density -1
                            mass 0.15
                          }
                        }
                      }
                    ]
                  }
                ]
                boundingObject USE upperLeg
                physics Physics {
                  density -1
                  mass 0.17
                }
              }
            ]
            name "solid(1)"
            boundingObject USE upperlegbodyconnector
            physics Physics {
              density -1
              mass 0.03
              centerOfMass [
                0 0 0
              ]
            }
          }
        }
        DEF BetterTorso Shape {
          appearance PBRAppearance {
            baseColor 0.1 0.4 0.65
          }
          geometry IndexedFaceSet {
            coord Coordinate {
              point [
                0 0 0
                0 0 0.2
                0 0.05 0
                0 0.05 0.2
                0 0.14 0.04
                0 0.14 0.16
                0.515 0 0
                0.515 0 0.2
                0.515 0.05 0
                0.515 0.05 0.2
                0.515 0.14 0.04
                0.515 0.14 0.16
              ]
            }
            coordIndex [
              0, 1, 2, -1, 2, 1, 3, -1, 2, 3, 4, -1, 4, 3, 5, -1, 1, 7, 3, -1, 3, 7, 9, -1, 3, 9, 5, -1, 5, 9, 11, -1, 4, 5, 11, -1, 4, 11, 10, -1, 4, 10, 8, -1, 2, 4, 8, -1, 0, 2, 6, -1, 2, 8, 6, -1, 0, 6, 1, -1, 1, 6, 7, -1, 6, 8, 7, -1, 7, 8, 9, -1, 8, 10, 9, -1, 10, 11, 9
            ]
          }
        }
        DEF shoulderHip4 Hinge2Joint {
          jointParameters HingeJointParameters {
            anchor 0.12 0.025 0
            minStop -0.5
            maxStop 0.5
          }
          jointParameters2 JointParameters {
            minStop -3.14
            maxStop 3.14
          }
          endPoint Solid {
            translation 0.12 0.025 -0.0125
            children [
              DEF upperlegbodyconnector Shape {
                appearance PBRAppearance {
                  baseColor 0.04 1 0.68
                }
                geometry Box {
                  size 0.05 0.05 0.025
                }
              }
              Solid {
                translation 0 -0.065 -0.0275
                children [
                  DEF upperLeg Shape {
                    appearance PBRAppearance {
                    }
                    geometry Box {
                      size 0.05 0.18 0.03
                    }
                  }
                  Transform {
                    translation 0 -0.11 0.026
                    children [
                      SliderJoint {
                        jointParameters JointParameters {
                          axis 0 1 0
                          maxStop 0.085
                          springConstant 2
                        }
                        endPoint Solid {
                          children [
                            SliderJoint {
                              jointParameters JointParameters {
                                axis 0 1 0
                                maxStop 0.04
                                springConstant 3000
                              }
                              endPoint Solid {
                                translation 0 -0.09 0
                                children [
                                  DEF foot Shape {
                                    appearance PBRAppearance {
                                      baseColor 1 0.2 0.1
                                    }
                                    geometry Capsule {
                                      height 0.03
                                      radius 0.01
                                    }
                                  }
                                ]
                                boundingObject USE foot
                                physics Physics {
                                  density -1
                                  mass 0.1
                                }
                              }
                            }
                            DEF lowerandupperlegconnector Shape {
                              appearance PBRAppearance {
                                baseColor 0.5 0.9 0.1
                              }
                              geometry Box {
                                size 0.025 0.06 0.02
                              }
                            }
                          ]
                          boundingObject USE lowerandupperlegconnector
                          physics Physics {
                            density -1
                            mass 0.15
                          }
                        }
                      }
                    ]
                  }
                ]
                boundingObject USE upperLeg
                physics Physics {
                  density -1
                  mass 0.17
                }
              }
            ]
            boundingObject USE upperlegbodyconnector
            physics Physics {
              density -1
              mass 0.03
            }
          }
        }
      ]
      boundingObject USE BetterTorso
      physics Physics {
        density -1
        mass 12
      }
    }
  ]
  name "robot(1)"
  physics Physics {
  }
  controller ""
  selfCollision TRUE
}
